<?xml version="1.0" ?>
<!-- =================================================================================== -->
<!-- |    This document was autogenerated by xacro from omni.urdf.xacro                | -->
<!-- |    EDITING THIS FILE BY HAND IS NOT RECOMMENDED                                 | -->
<!-- =================================================================================== -->
<robot name="omni_robot">
  
  <!-- Base of the robot -->
  <link name="base_link">
    <visual>
      <geometry>
        <box size="0.5 0.5 0.1"/>
        <!-- Placeholder dimensions: 50cm x 50cm x 10cm -->
      </geometry>
      <material name="blue">
        <color rgba="0.0 0.0 1.0 1.0"/>
      </material>
    </visual>
    <collision>
      <geometry>
        <box size="0.5 0.5 0.1"/>
      </geometry>
    </collision>
    <inertial>
      <mass value="10.0"/>
      <inertia ixx="0.2" ixy="0.0" ixz="0.0" iyy="0.2" iyz="0.0" izz="0.2"/>
    </inertial>
  </link>
  <!-- LIDAR Sensor -->
  <link name="lidar_link">
    <visual>
      <geometry>
        <cylinder length="0.05" radius="0.1"/>
      </geometry>
      <material name="grey">
        <color rgba="0.5 0.5 0.5 1.0"/>
      </material>
    </visual>
    <collision>
      <geometry>
        <cylinder length="0.05" radius="0.1"/>
      </geometry>
    </collision>
    <inertial>
      <mass value="0.5"/>
      <inertia ixx="0.01" ixy="0.0" ixz="0.0" iyy="0.01" iyz="0.0" izz="0.01"/>
    </inertial>
  </link>
  <!-- LIDAR Joint -->
  <joint name="lidar_joint" type="fixed">
    <parent link="base_link"/>
    <child link="lidar_link"/>
    <origin rpy="0 0 0" xyz="0 0 0.1"/>
    <!-- Positioned on top of the base -->
  </joint>
  <link name="wheel_1_link">
    <visual>
      <geometry>
        <cylinder length="0.05" radius="0.05"/>
        <!-- Placeholder dimensions: 10cm diameter, 5cm width -->
      </geometry>
      <material name="black">
        <color rgba="0.0 0.0 0.0 1.0"/>
      </material>
    </visual>
    <collision>
      <geometry>
        <cylinder length="0.05" radius="0.05"/>
      </geometry>
    </collision>
    <inertial>
      <mass value="1.0"/>
      <inertia ixx="0.005" ixy="0.0" ixz="0.0" iyy="0.005" iyz="0.0" izz="0.005"/>
    </inertial>
  </link>
  <joint name="wheel_1_joint" type="continuous">
    <parent link="base_link"/>
    <child link="wheel_1_link"/>
    <origin rpy="0 0 0" xyz="0.25 0.25 -0.05"/>
    <axis xyz="0 1 0"/>
    <!-- Rotation around the Y-axis -->
  </joint>
  <link name="wheel_2_link">
    <visual>
      <geometry>
        <cylinder length="0.05" radius="0.05"/>
        <!-- Placeholder dimensions: 10cm diameter, 5cm width -->
      </geometry>
      <material name="black">
        <color rgba="0.0 0.0 0.0 1.0"/>
      </material>
    </visual>
    <collision>
      <geometry>
        <cylinder length="0.05" radius="0.05"/>
      </geometry>
    </collision>
    <inertial>
      <mass value="1.0"/>
      <inertia ixx="0.005" ixy="0.0" ixz="0.0" iyy="0.005" iyz="0.0" izz="0.005"/>
    </inertial>
  </link>
  <joint name="wheel_2_joint" type="continuous">
    <parent link="base_link"/>
    <child link="wheel_2_link"/>
    <origin rpy="0 0 0" xyz="0.25 -0.25 -0.05"/>
    <axis xyz="0 1 0"/>
    <!-- Rotation around the Y-axis -->
  </joint>
  <link name="wheel_3_link">
    <visual>
      <geometry>
        <cylinder length="0.05" radius="0.05"/>
        <!-- Placeholder dimensions: 10cm diameter, 5cm width -->
      </geometry>
      <material name="black">
        <color rgba="0.0 0.0 0.0 1.0"/>
      </material>
    </visual>
    <collision>
      <geometry>
        <cylinder length="0.05" radius="0.05"/>
      </geometry>
    </collision>
    <inertial>
      <mass value="1.0"/>
      <inertia ixx="0.005" ixy="0.0" ixz="0.0" iyy="0.005" iyz="0.0" izz="0.005"/>
    </inertial>
  </link>
  <joint name="wheel_3_joint" type="continuous">
    <parent link="base_link"/>
    <child link="wheel_3_link"/>
    <origin rpy="0 0 0" xyz="-0.25 -0.25 -0.05"/>
    <axis xyz="0 1 0"/>
    <!-- Rotation around the Y-axis -->
  </joint>
  <link name="wheel_4_link">
    <visual>
      <geometry>
        <cylinder length="0.05" radius="0.05"/>
        <!-- Placeholder dimensions: 10cm diameter, 5cm width -->
      </geometry>
      <material name="black">
        <color rgba="0.0 0.0 0.0 1.0"/>
      </material>
    </visual>
    <collision>
      <geometry>
        <cylinder length="0.05" radius="0.05"/>
      </geometry>
    </collision>
    <inertial>
      <mass value="1.0"/>
      <inertia ixx="0.005" ixy="0.0" ixz="0.0" iyy="0.005" iyz="0.0" izz="0.005"/>
    </inertial>
  </link>
  <joint name="wheel_4_joint" type="continuous">
    <parent link="base_link"/>
    <child link="wheel_4_link"/>
    <origin rpy="0 0 0" xyz="-0.25 0.25 -0.05"/>
    <axis xyz="0 1 0"/>
    <!-- Rotation around the Y-axis -->
  </joint>
</robot>
